Workbook

Sheet Data Flows
A1: Site Name | G1: Data Flows
A2: Note: The naming convention for the connection names is of form [Server] to [Client], as that is the normal flow of status information. Inputs flow from the server to the client, and outputs flow from the client to the server.
A3: Connection | B3: Version | C3: Last Updated | D3: Instance Count | E3: From | F3: To | G3: Protocol | H3: Baud | I3: Client Device Name | J3: Client Port | K3: Client Address | L3: Client IP Address | M3: Server Device Name | N3: Server Port | O3: Server Address | P3: Server IP Address

Sheet PPC to RTU-1
A1: Site Name | G1: DNP3.0 | J1: PPC to RTU
A2: Last updated | C2: 45755 | D2: Device Type | E2: PPC | J2: The scalar is the multiplier to put the actual measurement value on the wire, and the divisor to take the actual measurement value off the wire.
A3: Index digits in name | C3: 4 | D3: Subsystem / Zone | E3: PPC
A6: List Index | B6: Availability | C6: Object | D6: Point Description | E6: Data Type | F6: DNP index | G6: Bit | H6: Device Point Name | I6: Alarm State | J6: On (1) State | K6: Off (0) State | L6: Units | M6: Scalar | N6: Min Count | O6: Max Count | P6: Min Value | Q6: Max Value | R6: Analog Alarm Limits | S6: Alarm Profile | T6: Historian Profile | U6: HMI Category | V6: RTAC Point Name | W6: Enumeration Table | X6: Comments
A7: 1 | B7: Avaiable | C7: Analog input | D7: Global_horizontal_irradiance_W_m2 | E7: 16-bit signed integer | F7: 18 | L7: W/m² | M7: 10 | N7: -32768 | O7: 32767 | P7: -3276.8 | Q7: 3276.7 | V7: AI_0018_Global_horizontal_irradiance_W_m2_W_per_m²
A8: 2 | B8: Avaiable | C8: Analog input | D8: Average_plant_atmospheric_pressure_bar | E8: 16-bit signed integer | F8: 19 | L8: bar | M8: 100 | N8: -32768 | O8: 32767 | P8: -327.68 | Q8: 327.67 | V8: AI_0019_Average_plant_atmospheric_pressure_bar_bar
A9: 3 | B9: Avaiable | C9: Analog input | D9: Average_plant_temperature_degC | E9: 16-bit signed integer | F9: 20 | L9: °C | M9: 100 | N9: -32768 | O9: 32767 | P9: -327.68 | Q9: 327.67 | V9: AI_0020_Average_plant_temperature_degC_°C
A10: 4 | B10: Avaiable | C10: Analog input | D10: Max_gen_limit_feedback_MW | E10: 16-bit signed integer | F10: 21 | L10: MW | M10: 100 | N10: -32768 | O10: 32767 | P10: -327.68 | Q10: 327.67 | V10: AI_0021_Max_gen_limit_feedback_MW_MW
A11: 5 | B11: Avaiable | C11: Analog input | D11: Potential_power_MW | E11: 16-bit signed integer | F11: 22 | L11: MW | M11: 100 | N11: -32768 | O11: 32767 | P11: -327.68 | Q11: 327.67 | V11: AI_0022_Potential_power_MW_MW
A12: 6 | B12: Avaiable | C12: Analog input | D12: Global_horizontal_irradiance_W_m2 | E12: 16-bit signed integer | F12: 23 | L12: W/m² | M12: 10 | N12: -32768 | O12: 32767 | P12: -3276.8 | Q12: 3276.7 | V12: AI_0023_Global_horizontal_irradiance_W_m2_W_per_m²
A13: 7 | B13: Avaiable | C13: Analog input | D13: Average_plant_atmospheric_pressure_bar | E13: 16-bit signed integer | F13: 24 | L13: bar | M13: 100 | N13: -32768 | O13: 32767 | P13: -327.68 | Q13: 327.67 | V13: AI_0024_Average_plant_atmospheric_pressure_bar_bar
A14: 8 | B14: Avaiable | C14: Analog input | D14: Average_plant_temperature_degC | E14: 16-bit signed integer | F14: 25 | L14: °C | M14: 100 | N14: -32768 | O14: 32767 | P14: -327.68 | Q14: 327.67 | V14: AI_0025_Average_plant_temperature_degC_°C
A15: 9 | B15: Avaiable | C15: Analog input | D15: Max_gen_limit_feedback_MW | E15: 16-bit signed integer | F15: 26 | L15: MW | M15: 100 | N15: -32768 | O15: 32767 | P15: -327.68 | Q15: 327.67 | V15: AI_0026_Max_gen_limit_feedback_MW_MW
A16: 10 | B16: Avaiable | C16: Analog input | D16: Potential_power_MW | E16: 16-bit signed integer | F16: 27 | L16: MW | M16: 100 | N16: -32768 | O16: 32767 | P16: -327.68 | Q16: 327.67 | V16: AI_0027_Potential_power_MW_MW
P47: =IFERROR(#REF!/#REF!,"") | Q47: =IFERROR(#REF!/#REF!,"")
P48: =IFERROR(#REF!/#REF!,"") | Q48: =IFERROR(#REF!/#REF!,"")
P49: =IFERROR(#REF!/#REF!,"") | Q49: =IFERROR(#REF!/#REF!,"")
P50: =IFERROR(#REF!/#REF!,"") | Q50: =IFERROR(#REF!/#REF!,"")
P51: =IFERROR(#REF!/#REF!,"") | Q51: =IFERROR(#REF!/#REF!,"")

Sheet Inverters to PPC - SG3600
A1: Site Name | G1: Modbus | K1: Inverters to PPC
A2: Last updated | C2: 45755 | D2: Device Type | E2: Sungrow SG3600UD | K2: The scalar is the multiplier to put the actual measurement value on the wire, and the divisor to take the actual measurement value off the wire.
A3: Index digits in name | C3: 5 | D3: Subsystem / Zone | E3: Inverters
A4: Device Register Base | C4: 1 | K4: CAUTION: Sungrow device uses multiple endian conventions on a per-register basis. Consult sungrow manual for endian convention rubric.
A5: Register Digits | C5: 6
A6: List Index | B6: Availability | C6: Modbus Table | D6: Point Description | E6: Data Type | F6: Ignition Modbus index | G6: Modbus Bit | H6: Modbus Register | I6: Device Point Name | J6: Alarm State | K6: On (1) State | L6: Off (0) State | M6: Units | N6: Scalar | O6: Min Count | P6: Max Count | Q6: Min Value | R6: Max Value | S6: Analog Alarm Limits | T6: Alarm Profile | U6: Historian Profile | V6: HMI Category | W6: RTAC Point Name | X6: Enumeration Table | Y6: Comments
A7: 1 | B7: Not Imported | C7: Input Register | D7: Protocol Number | E7: 32-bit unsigned integer | F7: 14999 | H7: 315000 | M7: unitless | O7: 0 | P7: 4294967295 | W7: IREG_14999_Protocol_Number | Y7: This point is not mapped to ignition
A8: 2 | B8: Not Imported | C8: Input Register | D8: Protocol Version | E8: 32-bit unsigned integer | F8: 15001 | H8: 315002 | M8: unitless | O8: 0 | P8: 4294967295 | W8: IREG_15001_Protocol_Version | Y8: This point is not mapped to ignition
A9: 3 | B9: Not Imported | C9: Input Register | D9: Serial Number | E9: String | F9: 15003 | H9: 315004 | W9: IREG_15003_Serial_Number | Y9: This point is not mapped to ignition
A10: 4 | B10: Not Imported | C10: Input Register | D10: Machine Type | E10: String | F10: 15011 | H10: 315012 | W10: IREG_15011_Machine_Type | Y10: This point is not mapped to ignition
A11: 5 | B11: Available | C11: Input Register | D11: U1 DC input #1 | E11: 16-bit signed integer | F11: 15029 | H11: 315030 | M11: A | N11: 10 | O11: -32768 | P11: 32767 | Q11: -3276.8 | R11: 3276.7 | W11: IREG_15029_U1_DC_input_1_A
A12: 6 | B12: Available | C12: Input Register | D12: U1 DC input #2 | E12: 16-bit signed integer | F12: 15030 | H12: 315031 | M12: A | N12: 10 | O12: -32768 | P12: 32767 | Q12: -3276.8 | R12: 3276.7 | W12: IREG_15030_U1_DC_input_2_A
A13: 7 | B13: Available | C13: Input Register | D13: U1 DC input #3 | E13: 16-bit signed integer | F13: 15031 | H13: 315032 | M13: A | N13: 10 | O13: -32768 | P13: 32767 | Q13: -3276.8 | R13: 3276.7 | W13: IREG_15031_U1_DC_input_3_A
A14: 8 | B14: Available | C14: Input Register | D14: U1 DC input #4 | E14: 16-bit signed integer | F14: 15032 | H14: 315033 | M14: A | N14: 10 | O14: -32768 | P14: 32767 | Q14: -3276.8 | R14: 3276.7 | W14: IREG_15032_U1_DC_input_4_A
A15: 9 | B15: Available | C15: Input Register | D15: U1 DC input #5 | E15: 16-bit signed integer | F15: 15033 | H15: 315034 | M15: A | N15: 10 | O15: -32768 | P15: 32767 | Q15: -3276.8 | R15: 3276.7 | W15: IREG_15033_U1_DC_input_5_A
A16: 10 | B16: Available | C16: Input Register | D16: U1 DC input #6 | E16: 16-bit signed integer | F16: 15034 | H16: 315035 | M16: A | N16: 10 | O16: -32768 | P16: 32767 | Q16: -3276.8 | R16: 3276.7 | W16: IREG_15034_U1_DC_input_6_A
A17: 11 | B17: Available | C17: Input Register | D17: U1 DC input #7 | E17: 16-bit signed integer | F17: 15035 | H17: 315036 | M17: A | N17: 10 | O17: -32768 | P17: 32767 | Q17: -3276.8 | R17: 3276.7 | W17: IREG_15035_U1_DC_input_7_A
A18: 12 | B18: Available | C18: Input Register | D18: U1 DC input #8 | E18: 16-bit signed integer | F18: 15036 | H18: 315037 | M18: A | N18: 10 | O18: -32768 | P18: 32767 | Q18: -3276.8 | R18: 3276.7 | W18: IREG_15036_U1_DC_input_8_A
A19: 13 | B19: Available | C19: Input Register | D19: U1 DC input #9 | E19: 16-bit signed integer | F19: 15037 | H19: 315038 | M19: A | N19: 10 | O19: -32768 | P19: 32767 | Q19: -3276.8 | R19: 3276.7 | W19: IREG_15037_U1_DC_input_9_A
A20: 14 | B20: Available | C20: Input Register | D20: U1 DC input #10 | E20: 16-bit signed integer | F20: 15038 | H20: 315039 | M20: A | N20: 10 | O20: -32768 | P20: 32767 | Q20: -3276.8 | R20: 3276.7 | W20: IREG_15038_U1_DC_input_10_A
A21: 15 | B21: Available | C21: Input Register | D21: U1 DC input #11 | E21: 16-bit signed integer | F21: 15039 | H21: 315040 | M21: A | N21: 10 | O21: -32768 | P21: 32767 | Q21: -3276.8 | R21: 3276.7 | W21: IREG_15039_U1_DC_input_11_A
A22: 16 | B22: Available | C22: Input Register | D22: U1 DC input #12 | E22: 16-bit signed integer | F22: 15040 | H22: 315041 | M22: A | N22: 10 | O22: -32768 | P22: 32767 | Q22: -3276.8 | R22: 3276.7 | W22: IREG_15040_U1_DC_input_12_A
... A42: 36 | B42: Available | C42: Input Register | D42: U2 DC input #16 | E42: 16-bit signed integer | F42: 15062 | H42: 315063 | M42: A | N42: 10 | O42: -32768 | P42: 32767 | Q42: -3276.8 | R42: 3276.7 | W42: IREG_15062_U2_DC_input_16_A
A43: 37 | B43: Not Imported | C43: Input Register | D43: Device Type Code | E43: 16-bit unsigned integer | F43: 15069 | H43: 315070 | M43: unitless | O43: 0 | P43: 65535 | W43: IREG_15069_Device_Type_Code | Y43: This point is not mapped to ignition
A44: 38 | B44: Not Imported | C44: Input Register | D44: Rated active power | E44: 16-bit unsigned integer | F44: 15070 | H44: 315071 | M44: kW | N44: 10 | O44: 0 | P44: 65535 | Q44: 0 | R44: 6553.5 | W44: IREG_15070_Rated_active_power_kW | Y44: This point is not mapped to ignition
A45: 39 | B45: Available | C45: Input Register | D45: Daily Power yield | E45: 32-bit unsigned integer | F45: 15072 | H45: 315073 | M45: kWh | N45: 10 | O45: 0 | P45: 4294967295 | Q45: 0 | R45: 4.2949673e+08 | W45: IREG_15072_Daily_Power_yield_kWh
A46: 40 | B46: Available | C46: Input Register | D46: Monthly Power yield | E46: 32-bit unsigned integer | F46: 15074 | H46: 315075 | M46: kWh | N46: 1 | O46: 0 | P46: 4294967295 | Q46: 0 | R46: 4294967295 | W46: IREG_15074_Monthly_Power_yield_kWh | Y46: This point is not mapped to ignition
A47: 41 | B47: Available | C47: Input Register | D47: Total Power yield | E47: 32-bit unsigned integer | F47: 15076 | H47: 315077 | M47: kWh | N47: 1 | O47: 0 | P47: 4294967295 | Q47: 0 | R47: 4294967295 | W47: IREG_15076_Total_Power_yield_kWh
A48: 42 | B48: Available | C48: Input Register | D48: CO2 emission reduction | E48: 32-bit unsigned integer | F48: 15078 | H48: 315079 | M48: kg | N48: 1 | O48: 0 | P48: 4294967295 | Q48: 0 | R48: 4294967295 | W48: IREG_15078_CO2_emission_reduction_kg | Y48: This point is not mapped to ignition
A49: 43 | B49: Available | C49: Input Register | D49: Daily grid connected minutes | E49: 16-bit unsigned integer | F49: 15080 | H49: 315081 | M49: min | N49: 1 | O49: 0 | P49: 65535 | Q49: 0 | R49: 65535 | W49: IREG_15080_Daily_grid_connected_minutes_min | Y49: This point is not mapped to ignition
A50: 44 | B50: Available | C50: Input Register | D50: Total Running Hours | E50: 32-bit unsigned integer | F50: 15081 | H50: 315082 | M50: hr | N50: 1 | O50: 0 | P50: 4294967295 | Q50: 0 | R50: 4294967295 | W50: IREG_15081_Total_Running_Hours_hr
A51: 45 | B51: Available | C51: Input Register | D51: Total DC Power | E51: 32-bit unsigned integer | F51: 15091 | H51: 315092 | M51: W | N51: 1 | O51: 0 | P51: 4294967295 | Q51: 0 | R51: 4294967295 | W51: IREG_15091_Total_DC_Power_W
A52: 46 | B52: Available | C52: Input Register | D52: A-B Line Voltage | E52: 16-bit unsigned integer | F52: 15093 | H52: 315094 | M52: V | N52: 10 | O52: 0 | P52: 65535 | Q52: 0 | R52: 6553.5 | W52: IREG_15093_A_B_Line_Voltage_V
A53: 47 | B53: Available | C53: Input Register | D53: B-C Line Voltage | E53: 16-bit unsigned integer | F53: 15094 | H53: 315095 | M53: V | N53: 10 | O53: 0 | P53: 65535 | Q53: 0 | R53: 6553.5 | W53: IREG_15094_B_C_Line_Voltage_V
A54: 48 | B54: Available | C54: Input Register | D54: C-A Line Voltage | E54: 16-bit unsigned integer | F54: 15095 | H54: 315096 | M54: V | N54: 10 | O54: 0 | P54: 65535 | Q54: 0 | R54: 6553.5 | W54: IREG_15095_C_A_Line_Voltage_V
A55: 49 | B55: Available | C55: Input Register | D55: Phase A Current | E55: 16-bit unsigned integer | F55: 15096 | H55: 315097 | M55: A | N55: 10 | O55: 0 | P55: 65535 | Q55: 0 | R55: 6553.5 | W55: IREG_15096_Phase_A_Current_A
A56: 50 | B56: Available | C56: Input Register | D56: Phase B Current | E56: 16-bit unsigned integer | F56: 15097 | H56: 315098 | M56: A | N56: 10 | O56: 0 | P56: 65535 | Q56: 0 | R56: 6553.5 | W56: IREG_15097_Phase_B_Current_A
A57: 51 | B57: Available | C57: Input Register | D57: Phase C Current | E57: 16-bit unsigned integer | F57: 15098 | H57: 315099 | M57: A | N57: 10 | O57: 0 | P57: 65535 | Q57: 0 | R57: 6553.5 | W57: IREG_15098_Phase_C_Current_A
A58: 52 | B58: Available | C58: Input Register | D58: Total active power | E58: 32-bit unsigned integer | F58: 15099 | H58: 315100 | M58: W | N58: 1 | O58: 0 | P58: 4294967295 | Q58: 0 | R58: 4294967295 | W58: IREG_15099_Total_active_power_W
A59: 53 | B59: Available | C59: Input Register | D59: Total reactive power | E59: 32-bit signed integer | F59: 15101 | H59: 315102 | M59: var | N59: 1 | O59: -2147483648 | P59: 2147483647 | Q59: -2147483648 | R59: 2147483647 | W59: IREG_15101_Total_reactive_power_var
...

Sheet Inverters to PPC - SG4400UD
A1: ='Data Flows'!A1 -> Site Name | G1: Modbus | K1: Inverters to PPC-1
A2: Last updated | C2: 45383 | D2: Device Type | E2: Sungrow SG4400UD | K2: The scalar is the multiplier to put the actual measurement value on the wire, and the divisor to take the actual measurement value off the wire.
A3: Index digits in name | C3: 5 | D3: Subsystem / Zone | E3: Inverters
A4: Device Register Base | C4: 1 | K4: CAUTION: Sungrow device uses multiple endian conventions on a per-register basis. Consult sungrow manual for endian convention rubric.
A5: Register Digits | C5: 6
A6: List Index | B6: Availability | C6: Modbus Table | D6: Point Description | E6: Data Type | F6: RTAC Modbus index | G6: Modbus Bit | H6: Modbus Register | I6: Device Point Name | J6: Alarm State | K6: On (1) State | L6: Off (0) State | M6: Units | N6: Scalar | O6: Min Count | P6: Max Count | Q6: Min Value | R6: Max Value | S6: Analog Alarm Limits | T6: Alarm Profile | U6: Historian Profile | V6: HMI Category | W6: RTAC Point Name | X6: Enumeration Table | Y6: Comments
A7: 1 | B7: Not Imported | C7: Input Register | D7: Protocol Number | E7: 32-bit unsigned integer | F7: 14999 | H7: 315000 | M7: unitless | O7: 0 | P7: 4294967295 | W7: IREG_14999_Protocol_Number | Y7: This point is not mapped to ignition
A8: 2 | B8: Not Imported | C8: Input Register | D8: Protocol Version | E8: 32-bit unsigned integer | F8: 15001 | H8: 315002 | M8: unitless | O8: 0 | P8: 4294967295 | W8: IREG_15001_Protocol_Version | Y8: This point is not mapped to ignition
A9: 3 | B9: Not Imported | C9: Input Register | D9: Serial Number | E9: String | F9: 15003 | H9: 315004 | W9: IREG_15003_Serial_Number | Y9: This point is not mapped to ignition
A10: 4 | B10: Not Imported | C10: Input Register | D10: Machine Model | E10: String | F10: 15011 | H10: 315012 | W10: IREG_15011_Machine_Model | Y10: This point is not mapped to ignition
A11: 5 | B11: Available | C11: Input Register | D11: Device Type Code | E11: 16-bit unsigned integer | F11: 15069 | H11: 315070 | M11: unitless | N11: 1 | O11: 0 | P11: 65535 | Q11: 0 | R11: 65535 | W11: IREG_15069_Device_Type_Code | Y11: This point is not mapped to ignition
A12: 6 | B12: Available | C12: Input Register | D12: Rated active power | E12: 16-bit unsigned integer | F12: 15070 | H12: 315071 | M12: kW | N12: 10 | O12: 0 | P12: 65535 | Q12: 0 | R12: 6553.5 | W12: IREG_15070_Rated_active_power_kW | Y12: This point is not mapped to ignition
A13: 7 | B13: Available | C13: Input Register | D13: Daily Power yield | E13: 32-bit unsigned integer | F13: 15072 | H13: 315073 | M13: kWh | N13: 10 | O13: 0 | P13: 4294967295 | Q13: 0 | R13: 4.2949673e+08 | W13: IREG_15072_Daily_Power_yield_kWh
A14: 8 | B14: Available | C14: Input Register | D14: Monthly Power yield | E14: 32-bit unsigned integer | F14: 15074 | H14: 315075 | M14: kWh | N14: 1 | O14: 0 | P14: 4294967295 | Q14: 0 | R14: 4294967295 | W14: IREG_15074_Monthly_Power_yield_kWh | Y14: This point is not mapped to ignition
A15: 9 | B15: Available | C15: Input Register | D15: Total Power yield | E15: 32-bit unsigned integer | F15: 15076 | H15: 315077 | M15: kWh | N15: 1 | O15: 0 | P15: 4294967295 | Q15: 0 | R15: 4294967295 | W15: IREG_15076_Total_Power_yield_kWh
A16: 10 | B16: Available | C16: Input Register | D16: CO2 emission reduction | E16: 32-bit unsigned integer | F16: 15078 | H16: 315079 | M16: kg | N16: 1 | O16: 0 | P16: 4294967295 | Q16: 0 | R16: 4294967295 | W16: IREG_15078_CO2_emission_reduction_kg | Y16: This point is not mapped to ignition
A17: 11 | B17: Available | C17: Input Register | D17: Daily grid connected minutes | E17: 16-bit unsigned integer | F17: 15080 | H17: 315081 | M17: min | N17: 1 | O17: 0 | P17: 65535 | Q17: 0 | R17: 65535 | W17: IREG_15080_Daily_grid_connected_minutes_min | Y17: This point is not mapped to ignition
A18: 12 | B18: Available | C18: Input Register | D18: Total Running Hours | E18: 32-bit unsigned integer | F18: 15081 | H18: 315082 | M18: hr | N18: 1 | O18: 0 | P18: 4294967295 | Q18: 0 | R18: 4294967295 | W18: IREG_15081_Total_Running_Hours_hr
A19: 13 | B19: Available | C19: Input Register | D19: Total DC Power | E19: 32-bit signed integer | F19: 15091 | H19: 315092 | M19: W | N19: 1 | O19: -2147483648 | P19: 2147483647 | Q19: -2147483648 | R19: 2147483647 | W19: IREG_15091_Total_DC_Power_W
A20: 14 | B20: Available | C20: Input Register | D20: A-B Line Voltage | E20: 16-bit unsigned integer | F20: 15093 | H20: 315094 | M20: V | N20: 10 | O20: 0 | P20: 65535 | Q20: 0 | R20: 6553.5 | W20: IREG_15093_A_B_Line_Voltage_V
A21: 15 | B21: Available | C21: Input Register | D21: B-C Line Voltage | E21: 16-bit unsigned integer | F21: 15094 | H21: 315095 | M21: V | N21: 10 | O21: 0 | P21: 65535 | Q21: 0 | R21: 6553.5 | W21: IREG_15094_B_C_Line_Voltage_V
A22: 16 | B22: Available | C22: Input Register | D22: C-A Line Voltage | E22: 16-bit unsigned integer | F22: 15095 | H22: 315096 | M22: V | N22: 10 | O22: 0 | P22: 65535 | Q22: 0 | R22: 6553.5 | W22: IREG_15095_C_A_Line_Voltage_V
A23: 17 | B23: Available | C23: Input Register | D23: Phase A Current | E23: 16-bit unsigned integer | F23: 15096 | H23: 315097 | M23: A | N23: 10 | O23: 0 | P23: 65535 | Q23: 0 | R23: 6553.5 | W23: IREG_15096_Phase_A_Current_A
A24: 18 | B24: Available | C24: Input Register | D24: Phase B Current | E24: 16-bit unsigned integer | F24: 15097 | H24: 315098 | M24: A | N24: 10 | O24: 0 | P24: 65535 | Q24: 0 | R24: 6553.5 | W24: IREG_15097_Phase_B_Current_A
A25: 19 | B25: Available | C25: Input Register | D25: Phase C Current | E25: 16-bit unsigned integer | F25: 15098 | H25: 315099 | M25: A | N25: 10 | O25: 0 | P25: 65535 | Q25: 0 | R25: 6553.5 | W25: IREG_15098_Phase_C_Current_A
A26: 20 | B26: Available | C26: Input Register | D26: Total active power | E26: 32-bit signed integer | F26: 15099 | H26: 315100 | M26: W | N26: 1 | O26: -2147483648 | P26: 2147483647 | Q26: -2147483648 | R26: 2147483647 | W26: IREG_15099_Total_active_power_W
A27: 21 | B27: Available | C27: Input Register | D27: Total reactive power | E27: 32-bit signed integer | F27: 15101 | H27: 315102 | M27: var | N27: 1 | O27: -2147483648 | P27: 2147483647 | Q27: -2147483648 | R27: 2147483647 | W27: IREG_15101_Total_reactive_power_var
A28: 22 | B28: Available | C28: Input Register | D28: Total appearant power | E28: 32-bit unsigned integer | F28: 15103 | H28: 315104 | M28: VA | N28: 1 | O28: 0 | P28: 4294967295 | Q28: 0 | R28: 4294967295 | W28: IREG_15103_Total_appearant_power_VA | Y28: This point is not mapped to ignition
A29: 23 | B29: Available | C29: Input Register | D29: Power Factor | E29: 16-bit signed integer | F29: 15105 | H29: 315106 | M29: PU | N29: 1000 | O29: -32768 | P29: 32767 | Q29: -32.768 | R29: 32.767 | W29: IREG_15105_Power_Factor_PU
A30: 24 | B30: Available | C30: Input Register | D30: Frequency | E30: 16-bit unsigned integer | F30: 15106 | H30: 315107 | M30: Hz | N30: 10 | O30: 0 | P30: 65535 | Q30: 0 | R30: 6553.5 | W30: IREG_15106_Frequency_Hz
A31: 25 | B31: Not Imported | C31: Input Register | D31: Rated reactive power | E31: 16-bit unsigned integer | F31: 15107 | H31: 315108 | M31: kvar | N31: 10 | O31: 0 | P31: 65535 | Q31: 0 | R31: 6553.5 | W31: IREG_15107_Rated_reactive_power_kvar | Y31: This point is not mapped to ignition
A32: 26 | B32: Available | C32: Input Register | D32: Power limit actual value feedback | E32: 32-bit unsigned integer | F32: 15108 | H32: 315109 | M32: W | N32: 1 | O32: 0 | P32: 4294967295 | Q32: 0 | R32: 4294967295 | W32: IREG_15108_Power_limit_actual_value_feedback_W
A33: 27 | B33: Available | C33: Input Register | D33: Reactive power adjustment actual value feedback | E33: 32-bit signed integer | F33: 15110 | H33: 315111 | M33: var | N33: 1 | O33: -2147483648 | P33: 2147483647 | Q33: -2147483648 | R33: 2147483647 | W33: IREG_15110_Reactive_power_adjustment_actual_value_feedback_var
A34: 28 | B34: Available | C34: Input Register | D34: Power factor feedback | E34: 16-bit signed integer | F34: 15112 | H34: 315113 | M34: PU | N34: 1000 | O34: -32768 | P34: 32767 | Q34: -32.768 | R34: 32.767 | W34: IREG_15112_Power_factor_feedback_PU
A35: 29 | B35: Available | C35: Input Register | D35: Transformer node state | E35: 16-bit bitfield | F35: 15113 | H35: 315114 | W35: IREG_15113_Transformer_node_state
A36: 30 | B36: Available | C36: Input Register | D36: Transformer gas buildup trip | E36: Boolean | F36: 15113 | G36: 0 | H36: 315114.0 | J36: On (1) | K36: Tripped | L36: Normal | W36: IREG_15113_Transformer_gas_buildup_trip
A37: 31 | B37: Available | C37: Input Register | D37: Transformer gas buildup alarm | E37: Boolean | F37: 15113 | G37: 1 | H37: 315114.1 | J37: On (1) | K37: Alarm | L37: Normal | W37: IREG_15113_Transformer_gas_buildup_alarm
A38: 32 | B38: Available | C38: Input Register | D38: Transformer oil temperature alarm | E38: Boolean | F38: 15113 | G38: 2 | H38: 315114.2 | J38: On (1) | K38: Alarm | L38: Normal | W38: IREG_15113_Transformer_oil_temperature_alarm
A39: 33 | B39: Available | C39: Input Register | D39: Transformer oil temperature trip | E39: Boolean | F39: 15113 | G39: 3 | H39: 315114.3 | J39: On (1) | K39: Tripped | L39: Normal | W39: IREG_15113_Transformer_oil_temperature_trip
A40: 34 | B40: Available | C40: Input Register | D40: Transformer low oil level trip | E40: Boolean | F40: 15113 | G40: 4 | H40: 315114.4 | J40: On (1) | K40: Tripped | L40: Normal | W40: IREG_15113_Transformer_low_oil_level_trip
...

Sheet Met Tower to PPC
A1: ='Data Flows'!A1 -> Site Name | G1: Modbus | K1: Met Tower to PPC
A2: Last updated | C2: 45082 | D2: Device Type | E2: Groundwork Zenith | K2: The scalar is the multiplier to put the actual measurement value on the wire, and the divisor to take the actual measurement value off the wire.
A3: Index digits in name | C3: 4 | D3: Subsystem / Zone | E3: Environmental
A4: Device Register Base | C4: 1
A5: Register Digits | C5: 5
A6: List Index | B6: Availability | C6: Modbus Table | D6: Point Description | E6: Data Type | F6: RTAC Modbus index | G6: Modbus Bit | H6: Modbus Register | I6: Device Point Name | J6: Alarm State | K6: On (1) State | L6: Off (0) State | M6: Units | N6: Scalar | O6: Min Count | P6: Max Count | Q6: Min Value | R6: Max Value | S6: Analog Alarm Limits | T6: Alarm Profile | U6: Historian Profile | V6: HMI Category | W6: RTAC Point Name | X6: Enumeration Table | Y6: Comments
A7: 1 | B7: Available | C7: Holding Register | D7: Scan count | E7: 32-bit float | F7: 0 | H7: 40001 | M7: s | N7: 1 | O7: -3.4028235e+38 | P7: 3.4028235e+38 | Q7: -3.4028235e+38 | R7: 3.4028235e+38 | W7: HREG_0000_Scan_count_s
A8: 2 | B8: Available | C8: Holding Register | D8: Skipped scans | E8: 32-bit float | F8: 2 | H8: 40003 | M8: count | N8: 1 | O8: -3.4028235e+38 | P8: 3.4028235e+38 | Q8: -3.4028235e+38 | R8: 3.4028235e+38 | W8: HREG_0002_Skipped_scans_count
A9: 3 | B9: Available | C9: Holding Register | D9: Logger voltage | E9: 32-bit float | F9: 4 | H9: 40005 | M9: V | N9: 1 | O9: -3.4028235e+38 | P9: 3.4028235e+38 | Q9: -3.4028235e+38 | R9: 3.4028235e+38 | W9: HREG_0004_Logger_voltage_V
A10: 4 | B10: Available | C10: Holding Register | D10: Logger temp | E10: 32-bit float | F10: 6 | H10: 40007 | M10: DegC | N10: 1 | O10: -3.4028235e+38 | P10: 3.4028235e+38 | Q10: -3.4028235e+38 | R10: 3.4028235e+38 | W10: HREG_0006_Logger_temp_DegC
A11: 5 | B11: Available | C11: Holding Register | D11: Skipped slow scans | E11: 32-bit float | F11: 8 | H11: 40009 | M11: count | N11: 1 | O11: -3.4028235e+38 | P11: 3.4028235e+38 | Q11: -3.4028235e+38 | R11: 3.4028235e+38 | W11: HREG_0008_Skipped_slow_scans_count
A12: 6 | B12: Available | C12: Holding Register | D12: Logger lithium | E12: 32-bit float | F12: 10 | H12: 40011 | M12: V | N12: 1 | O12: -3.4028235e+38 | P12: 3.4028235e+38 | Q12: -3.4028235e+38 | R12: 3.4028235e+38 | W12: HREG_0010_Logger_lithium_V
A13: 7 | B13: Available | C13: Holding Register | D13: Logger low volt 12 | E13: 32-bit float | F13: 12 | H13: 40013 | M13: count | N13: 1 | O13: -3.4028235e+38 | P13: 3.4028235e+38 | Q13: -3.4028235e+38 | R13: 3.4028235e+38 | W13: HREG_0012_Logger_low_volt_12_count
A14: 8 | B14: Available | C14: Holding Register | D14: Solar zenith | E14: 32-bit float | F14: 16 | H14: 40017 | M14: degrees | N14: 1 | O14: -3.4028235e+38 | P14: 3.4028235e+38 | Q14: -3.4028235e+38 | R14: 3.4028235e+38 | W14: HREG_0016_Solar_zenith_degrees
A15: 9 | B15: Available | C15: Holding Register | D15: Solar elevation | E15: 32-bit float | F15: 18 | H15: 40019 | M15: degrees | N15: 1 | O15: -3.4028235e+38 | P15: 3.4028235e+38 | Q15: -3.4028235e+38 | R15: 3.4028235e+38 | W15: HREG_0018_Solar_elevation_degrees
A16: 10 | B16: Available | C16: Holding Register | D16: Solar azimuth | E16: 32-bit float | F16: 20 | H16: 40021 | M16: degrees | N16: 1 | O16: -3.4028235e+38 | P16: 3.4028235e+38 | Q16: -3.4028235e+38 | R16: 3.4028235e+38 | W16: HREG_0020_Solar_azimuth_degrees
A17: 11 | B17: Available | C17: Holding Register | D17: Heat state | E17: 32-bit float | F17: 22 | H17: 40023 | K17: On | L17: Off | M17: boolean | N17: 1 | O17: -3.4028235e+38 | P17: 3.4028235e+38 | Q17: -3.4028235e+38 | R17: 3.4028235e+38 | W17: HREG_0022_Heat_state_boolean
A18: 12 | B18: Available | C18: Holding Register | D18: Logger data map version | E18: 32-bit float | F18: 24 | H18: 40025 | M18: unitless | N18: 1 | O18: -3.4028235e+38 | P18: 3.4028235e+38 | Q18: -3.4028235e+38 | R18: 3.4028235e+38 | W18: HREG_0024_Logger_data_map_version
A19: 13 | B19: Available | C19: Holding Register | D19: Maint event | E19: 32-bit float | F19: 26 | H19: 40027 | K19: On | L19: Off | M19: boolean | N19: 1 | O19: -3.4028235e+38 | P19: 3.4028235e+38 | Q19: -3.4028235e+38 | R19: 3.4028235e+38 | W19: HREG_0026_Maint_event_boolean
A20: 14 | B20: Available | C20: Holding Register | D20: Logger AC power available | E20: 32-bit float | F20: 28 | H20: 40029 | K20: On | L20: Off | M20: boolean | N20: 1 | O20: -3.4028235e+38 | P20: 3.4028235e+38 | Q20: -3.4028235e+38 | R20: 3.4028235e+38 | W20: HREG_0028_Logger_AC_power_available_boolean | X20: 0 to 1
A21: 15 | B21: Available | C21: Holding Register | D21: Batt voltage | E21: 32-bit float | F21: 30 | H21: 40031 | M21: V | N21: 1 | O21: -3.4028235e+38 | P21: 3.4028235e+38 | Q21: -3.4028235e+38 | R21: 3.4028235e+38 | W21: HREG_0030_Batt_voltage_V
A22: 16 | B22: Available | C22: Holding Register | D22: Batt current | E22: 32-bit float | F22: 32 | H22: 40033 | M22: A | N22: 1 | O22: -3.4028235e+38 | P22: 3.4028235e+38 | Q22: -3.4028235e+38 | R22: 3.4028235e+38 | W22: HREG_0032_Batt_current_A
A23: 17 | B23: Available | C23: Holding Register | D23: Load current | E23: 32-bit float | F23: 34 | H23: 40035 | M23: A | N23: 1 | O23: -3.4028235e+38 | P23: 3.4028235e+38 | Q23: -3.4028235e+38 | R23: 3.4028235e+38 | W23: HREG_0034_Load_current_A
A24: 18 | B24: Available | C24: Holding Register | D24: Input voltage 1 | E24: 32-bit float | F24: 36 | H24: 40037 | M24: V | N24: 1 | O24: -3.4028235e+38 | P24: 3.4028235e+38 | Q24: -3.4028235e+38 | R24: 3.4028235e+38 | W24: HREG_0036_Input_voltage_1_V
A25: 19 | B25: Available | C25: Holding Register | D25: Chargesource | E25: 32-bit float | F25: 40 | H25: 40041 | M25: enumeration | N25: 1 | O25: -3.4028235e+38 | P25: 3.4028235e+38 | Q25: -3.4028235e+38 | R25: 3.4028235e+38 | W25: HREG_0040_Chargesource | Y25: 0 = None, 1 = Solar, 2 = AC Power
A26: 20 | B26: Available | C26: Holding Register | D26: Checkbattery | E26: 32-bit float | F26: 42 | H26: 40043 | K26: Alarm | L26: Alarm | M26: boolean | N26: 1 | O26: -3.4028235e+38 | P26: 3.4028235e+38 | Q26: -3.4028235e+38 | R26: 3.4028235e+38 | W26: HREG_0042_Checkbattery
A27: 21 | B27: Available | C27: Holding Register | D27: Input voltage 2 | E27: 32-bit float | F27: 44 | H27: 40045 | M27: V | N27: 1 | O27: -3.4028235e+38 | P27: 3.4028235e+38 | Q27: -3.4028235e+38 | R27: 3.4028235e+38 | W27: HREG_0044_Input_voltage_2_V
A28: 22 | B28: Available | C28: Holding Register | D28: POA | E28: 32-bit float | F28: 46 | H28: 40047 | M28: W/m2 | N28: 1 | O28: -3.4028235e+38 | P28: 3.4028235e+38 | Q28: -3.4028235e+38 | R28: 3.4028235e+38 | W28: HREG_0046_POA_W_per_m2
A29: 23 | B29: Available | C29: Holding Register | D29: POA temperature compensated | E29: 32-bit float | F29: 48 | H29: 40049 | M29: W/m2 | N29: 1 | O29: -3.4028235e+38 | P29: 3.4028235e+38 | Q29: -3.4028235e+38 | R29: 3.4028235e+38 | W29: HREG_0048_POA_temperature_compensated_W_per_m2
A30: 24 | B30: Available | C30: Holding Register | D30: POA temp | E30: 32-bit float | F30: 50 | H30: 40051 | M30: DegC | N30: 1 | O30: -3.4028235e+38 | P30: 3.4028235e+38 | Q30: -3.4028235e+38 | R30: 3.4028235e+38 | W30: HREG_0050_POA_temp_DegC
A31: 25 | B31: Available | C31: Holding Register | D31: GHI | E31: 32-bit float | F31: 52 | H31: 40053 | M31: W/m2 | N31: 1 | O31: -3.4028235e+38 | P31: 3.4028235e+38 | Q31: -3.4028235e+38 | R31: 3.4028235e+38 | W31: HREG_0052_GHI_W_per_m2
A32: 26 | B32: Available | C32: Holding Register | D32: GHI temperature compensated | E32: 32-bit float | F32: 54 | H32: 40055 | M32: W/m2 | N32: 1 | O32: -3.4028235e+38 | P32: 3.4028235e+38 | Q32: -3.4028235e+38 | R32: 3.4028235e+38 | W32: HREG_0054_GHI_temperature_compensated_W_per_m2
A33: 27 | B33: Available | C33: Holding Register | D33: GHI temp | E33: 32-bit float | F33: 56 | H33: 40057 | M33: DegC | N33: 1 | O33: -3.4028235e+38 | P33: 3.4028235e+38 | Q33: -3.4028235e+38 | R33: 3.4028235e+38 | W33: HREG_0056_GHI_temp_DegC
A34: 28 | B34: Available | C34: Holding Register | D34: Ambient temp | E34: 32-bit float | F34: 74 | H34: 40075 | M34: DegC | N34: 1 | O34: -3.4028235e+38 | P34: 3.4028235e+38 | Q34: -3.4028235e+38 | R34: 3.4028235e+38 | W34: HREG_0074_Ambient_temp_DegC
A35: 29 | B35: Available | C35: Holding Register | D35: Dew point | E35: 32-bit float | F35: 76 | H35: 40077 | M35: DegC | N35: 1 | O35: -3.4028235e+38 | P35: 3.4028235e+38 | Q35: -3.4028235e+38 | R35: 3.4028235e+38 | W35: HREG_0076_Dew_point_DegC
A36: 30 | B36: Available | C36: Holding Register | D36: RH | E36: 32-bit float | F36: 78 | H36: 40079 | M36: % | N36: 1 | O36: -3.4028235e+38 | P36: 3.4028235e+38 | Q36: -3.4028235e+38 | R36: 3.4028235e+38 | W36: HREG_0078_RH_pct
A37: 31 | B37: Available | C37: Holding Register | D37: Wind speed | E37: 32-bit float | F37: 80 | H37: 40081 | M37: m/s | N37: 1 | O37: -3.4028235e+38 | P37: 3.4028235e+38 | Q37: -3.4028235e+38 | R37: 3.4028235e+38 | W37: HREG_0080_Wind_speed_m_per_s
A38: 32 | B38: Available | C38: Holding Register | D38: Wind speed max | E38: 32-bit float | F38: 82 | H38: 40083 | M38: m/s | N38: 1 | O38: -3.4028235e+38 | P38: 3.4028235e+38 | Q38: -3.4028235e+38 | R38: 3.4028235e+38 | W38: HREG_0082_Wind_speed_max_m_per_s
... A117: 111 | B117: Available | C117: Holding Register | D117: RPOA hourly insolation | E117: 32-bit float | F117: 844 | H117: 40845 | M117: Wh/m2 | N117: 1 | O117: -3.4028235e+38 | P117: 3.4028235e+38 | Q117: -3.4028235e+38 | R117: 3.4028235e+38 | W117: HREG_0844_RPOA_hourly_insolation_Wh_per_m2
A118: 99 | B118: Available | C118: Holding Register | D118: Summary alarm | E118: 32-bit unsigned int | F118: 2000 | H118: 42001 | J118: On (1) | K118: Alarm | L118: Normal | W118: HREG_2000_Summary_alarm
...

Sheet Met Tower ALB to Ignition
A1: Speedway | G1: Modbus | K1: Met Tower with Albedometer to Ignition
A2: Last updated | C2: 45683 | D2: Device Type | E2: Groundwork Zenith | K2: The scalar is the multiplier to put the actual measurement value on the wire, and the divisor to take the actual measurement value off the wire.
A3: Index digits in name | C3: 4 | D3: Subsystem / Zone | E3: Environmental
A4: Device Register Base | C4: 1
A5: Register Digits | C5: 5
A6: List Index | B6: Availability | C6: Modbus Table | D6: Point Description | E6: Data Type | F6: RTAC Modbus index | G6: Modbus Bit | H6: Modbus Register | I6: Device Point Name | J6: Alarm State | K6: On (1) State | L6: Off (0) State | M6: Units | N6: Scalar | O6: Min Count | P6: Max Count | Q6: Min Value | R6: Max Value | S6: Analog Alarm Limits | T6: Alarm Profile | U6: Historian Profile | V6: HMI Category | W6: RTAC Point Name | X6: Enumeration Table | Y6: Comments
A7: 1 | B7: Available | C7: Holding Register | D7: Scan count | E7: 32-bit float | F7: 0 | H7: 40001 | M7: s | N7: 1 | O7: -3.4028235e+38 | P7: 3.4028235e+38 | Q7: =IFERROR(Table3335466[[#This Row],[Min Count]]/Table3335466[[#This Row],[Scalar]],"") -> -3.4028235e+38 | R7: =IFERROR(Table3335466[[#This Row],[Max Count]]/Table3335466[[#This Row],[Scalar]],"") -> 3.4028235e+38 | W7: HREG_0000_Scan_count_s
A8: 2 | B8: Available | C8: Holding Register | D8: Skipped scans | E8: 32-bit float | F8: 2 | H8: 40002 | M8: count | N8: 1 | O8: -3.4028235e+38 | P8: 3.4028235e+38 | Q8: =IFERROR(Table3335466[[#This Row],[Min Count]]/Table3335466[[#This Row],[Scalar]],"") -> -3.4028235e+38 | R8: =IFERROR(Table3335466[[#This Row],[Max Count]]/Table3335466[[#This Row],[Scalar]],"") -> 3.4028235e+38 | W8: HREG_0002_Skipped_scans_count
A9: 3 | B9: Available | C9: Holding Register | D9: Logger voltage | E9: 32-bit float | F9: 4 | H9: 40003 | M9: V | N9: 1 | O9: -3.4028235e+38 | P9: 3.4028235e+38 | Q9: =IFERROR(Table3335466[[#This Row],[Min Count]]/Table3335466[[#This Row],[Scalar]],"") -> -3.4028235e+38 | R9: =IFERROR(Table3335466[[#This Row],[Max Count]]/Table3335466[[#This Row],[Scalar]],"") -> 3.4028235e+38 | W9: HREG_0004_Logger_voltage_V
A10: 4 | B10: Available | C10: Holding Register | D10: Logger temp | E10: 32-bit float | F10: 6 | H10: 40004 | M10: DegC | N10: 1 | O10: -3.4028235e+38 | P10: 3.4028235e+38 | Q10: =IFERROR(Table3335466[[#This Row],[Min Count]]/Table3335466[[#This Row],[Scalar]],"") -> -3.4028235e+38 | R10: =IFERROR(Table3335466[[#This Row],[Max Count]]/Table3335466[[#This Row],[Scalar]],"") -> 3.4028235e+38 | W10: HREG_0006_Logger_temp_DegC
A11: 5 | B11: Available | C11: Holding Register | D11: Skipped slow scans | E11: 32-bit float | F11: 8 | H11: 40005 | M11: count | N11: 1 | O11: -3.4028235e+38 | P11: 3.4028235e+38 | Q11: =IFERROR(Table3335466[[#This Row],[Min Count]]/Table3335466[[#This Row],[Scalar]],"") -> -3.4028235e+38 | R11: =IFERROR(Table3335466[[#This Row],[Max Count]]/Table3335466[[#This Row],[Scalar]],"") -> 3.4028235e+38 | W11: HREG_0008_Skipped_slow_scans_count
A12: 6 | B12: Available | C12: Holding Register | D12: Logger lithium | E12: 32-bit float | F12: 10 | H12: 40006 | M12: V | N12: 1 | O12: -3.4028235e+38 | P12: 3.4028235e+38 | Q12: =IFERROR(Table3335466[[#This Row],[Min Count]]/Table3335466[[#This Row],[Scalar]],"") -> -3.4028235e+38 | R12: =IFERROR(Table3335466[[#This Row],[Max Count]]/Table3335466[[#This Row],[Scalar]],"") -> 3.4028235e+38 | W12: HREG_0010_Logger_lithium_V
A13: 7 | B13: Available | C13: Holding Register | D13: Logger low volt 12 | E13: 32-bit float | F13: 12 | H13: 40007 | M13: count | N13: 1 | O13: -3.4028235e+38 | P13: 3.4028235e+38 | Q13: =IFERROR(Table3335466[[#This Row],[Min Count]]/Table3335466[[#This Row],[Scalar]],"") -> -3.4028235e+38 | R13: =IFERROR(Table3335466[[#This Row],[Max Count]]/Table3335466[[#This Row],[Scalar]],"") -> 3.4028235e+38 | W13: HREG_0012_Logger_low_volt_12_count
A14: 8 | B14: Available | C14: Holding Register | D14: Solar zenith | E14: 32-bit float | F14: 16 | H14: 40008 | M14: degrees | N14: 1 | O14: -3.4028235e+38 | P14: 3.4028235e+38 | Q14: =IFERROR(Table3335466[[#This Row],[Min Count]]/Table3335466[[#This Row],[Scalar]],"") -> -3.4028235e+38 | R14: =IFERROR(Table3335466[[#This Row],[Max Count]]/Table3335466[[#This Row],[Scalar]],"") -> 3.4028235e+38 | W14: HREG_0016_Solar_zenith_degrees
A15: 9 | B15: Available | C15: Holding Register | D15: Solar elevation | E15: 32-bit float | F15: 18 | H15: 40009 | M15: degrees | N15: 1 | O15: -3.4028235e+38 | P15: 3.4028235e+38 | Q15: =IFERROR(Table3335466[[#This Row],[Min Count]]/Table3335466[[#This Row],[Scalar]],"") -> -3.4028235e+38 | R15: =IFERROR(Table3335466[[#This Row],[Max Count]]/Table3335466[[#This Row],[Scalar]],"") -> 3.4028235e+38 | W15: HREG_0018_Solar_elevation_degrees
A16: 10 | B16: Available | C16: Holding Register | D16: Solar azimuth | E16: 32-bit float | F16: 20 | H16: 40010 | M16: degrees | N16: 1 | O16: -3.4028235e+38 | P16: 3.4028235e+38 | Q16: =IFERROR(Table3335466[[#This Row],[Min Count]]/Table3335466[[#This Row],[Scalar]],"") -> -3.4028235e+38 | R16: =IFERROR(Table3335466[[#This Row],[Max Count]]/Table3335466[[#This Row],[Scalar]],"") -> 3.4028235e+38 | W16: HREG_0020_Solar_azimuth_degrees
A17: 11 | B17: Available | C17: Holding Register | D17: Heat state | E17: 32-bit float | F17: 22 | H17: 40011 | K17: On | L17: Off | M17: boolean | N17: 1 | O17: -3.4028235e+38 | P17: 3.4028235e+38 | Q17: =IFERROR(Table3335466[[#This Row],[Min Count]]/Table3335466[[#This Row],[Scalar]],"") -> -3.4028235e+38 | R17: =IFERROR(Table3335466[[#This Row],[Max Count]]/Table3335466[[#This Row],[Scalar]],"") -> 3.4028235e+38 | W17: HREG_0022_Heat_state_boolean
A18: 12 | B18: Available | C18: Holding Register | D18: Logger data map version | E18: 32-bit float | F18: 24 | H18: 40012 | M18: unitless | N18: 1 | O18: -3.4028235e+38 | P18: 3.4028235e+38 | Q18: =IFERROR(Table3335466[[#This Row],[Min Count]]/Table3335466[[#This Row],[Scalar]],"") -> -3.4028235e+38 | R18: =IFERROR(Table3335466[[#This Row],[Max Count]]/Table3335466[[#This Row],[Scalar]],"") -> 3.4028235e+38 | W18: HREG_0024_Logger_data_map_version
A19: 13 | B19: Available | C19: Holding Register | D19: Maint event | E19: 32-bit float | F19: 26 | H19: 40013 | K19: On | L19: Off | M19: boolean | N19: 1 | O19: -3.4028235e+38 | P19: 3.4028235e+38 | Q19: =IFERROR(Table3335466[[#This Row],[Min Count]]/Table3335466[[#This Row],[Scalar]],"") -> -3.4028235e+38 | R19: =IFERROR(Table3335466[[#This Row],[Max Count]]/Table3335466[[#This Row],[Scalar]],"") -> 3.4028235e+38 | W19: HREG_0026_Maint_event_boolean
A20: 14 | C20: Holding Register | D20: Logger AC power | E20: 32-bit float | F20: 28 | H20: 40014 | K20: On | L20: Off | M20: boolean | N20: 1 | O20: -3.4028235e+38 | P20: 3.4028235e+38 | Q20: =IFERROR(Table3335466[[#This Row],[Min Count]]/Table3335466[[#This Row],[Scalar]],"") -> -3.4028235e+38 | R20: =IFERROR(Table3335466[[#This Row],[Max Count]]/Table3335466[[#This Row],[Scalar]],"") -> 3.4028235e+38 | W20: HREG_0028_Logger_AC_power_boolean
A21: 15 | B21: Available | C21: Holding Register | D21: Batt voltage | E21: 32-bit float | F21: 30 | H21: 40015 | M21: V | N21: 1 | O21: -3.4028235e+38 | P21: 3.4028235e+38 | Q21: =IFERROR(Table3335466[[#This Row],[Min Count]]/Table3335466[[#This Row],[Scalar]],"") -> -3.4028235e+38 | R21: =IFERROR(Table3335466[[#This Row],[Max Count]]/Table3335466[[#This Row],[Scalar]],"") -> 3.4028235e+38 | W21: HREG_0030_Batt_voltage_V
A22: 16 | B22: Available | C22: Holding Register | D22: Batt current | E22: 32-bit float | F22: 32 | H22: 40016 | M22: A | N22: 1 | O22: -3.4028235e+38 | P22: 3.4028235e+38 | Q22: =IFERROR(Table3335466[[#This Row],[Min Count]]/Table3335466[[#This Row],[Scalar]],"") -> -3.4028235e+38 | R22: =IFERROR(Table3335466[[#This Row],[Max Count]]/Table3335466[[#This Row],[Scalar]],"") -> 3.4028235e+38 | W22: HREG_0032_Batt_current_A
A23: 17 | B23: Available | C23: Holding Register | D23: Load current | E23: 32-bit float | F23: 34 | H23: 40017 | M23: A | N23: 1 | O23: -3.4028235e+38 | P23: 3.4028235e+38 | Q23: =IFERROR(Table3335466[[#This Row],[Min Count]]/Table3335466[[#This Row],[Scalar]],"") -> -3.4028235e+38 | R23: =IFERROR(Table3335466[[#This Row],[Max Count]]/Table3335466[[#This Row],[Scalar]],"") -> 3.4028235e+38 | W23: HREG_0034_Load_current_A
A24: 18 | B24: Available | C24: Holding Register | D24: Input voltage 1 | E24: 32-bit float | F24: 36 | H24: 40018 | M24: V | N24: 1 | O24: -3.4028235e+38 | P24: 3.4028235e+38 | Q24: =IFERROR(Table3335466[[#This Row],[Min Count]]/Table3335466[[#This Row],[Scalar]],"") -> -3.4028235e+38 | R24: =IFERROR(Table3335466[[#This Row],[Max Count]]/Table3335466[[#This Row],[Scalar]],"") -> 3.4028235e+38 | W24: HREG_0036_Input_voltage_1_V
A25: 19 | B25: Available | C25: Holding Register | D25: Input current | E25: 32-bit float | F25: 38 | H25: 40019 | M25: A | N25: 1 | O25: -3.4028235e+38 | P25: 3.4028235e+38 | Q25: =IFERROR(Table3335466[[#This Row],[Min Count]]/Table3335466[[#This Row],[Scalar]],"") -> -3.4028235e+38 | R25: =IFERROR(Table3335466[[#This Row],[Max Count]]/Table3335466[[#This Row],[Scalar]],"") -> 3.4028235e+38 | W25: HREG_0038_Input_current_A
A26: 20 | B26: Available | C26: Holding Register | D26: Chargesource | E26: 32-bit float | F26: 40 | H26: 40020 | M26: unitless | N26: 1 | O26: -3.4028235e+38 | P26: 3.4028235e+38 | Q26: =IFERROR(Table3335466[[#This Row],[Min Count]]/Table3335466[[#This Row],[Scalar]],"") -> -3.4028235e+38 | R26: =IFERROR(Table3335466[[#This Row],[Max Count]]/Table3335466[[#This Row],[Scalar]],"") -> 3.4028235e+38 | W26: HREG_0040_Chargesource
A27: 21 | B27: Available | C27: Holding Register | D27: Checkbattery | E27: 32-bit float | F27: 42 | H27: 40021 | M27: unitless | N27: 1 | O27: -3.4028235e+38 | P27: 3.4028235e+38 | Q27: =IFERROR(Table3335466[[#This Row],[Min Count]]/Table3335466[[#This Row],[Scalar]],"") -> -3.4028235e+38 | R27: =IFERROR(Table3335466[[#This Row],[Max Count]]/Table3335466[[#This Row],[Scalar]],"") -> 3.4028235e+38 | W27: HREG_0042_Checkbattery
A28: 22 | B28: Available | C28: Holding Register | D28: Input voltage 2 | E28: 32-bit float | F28: 44 | H28: 40022 | M28: V | N28: 1 | O28: -3.4028235e+38 | P28: 3.4028235e+38 | Q28: =IFERROR(Table3335466[[#This Row],[Min Count]]/Table3335466[[#This Row],[Scalar]],"") -> -3.4028235e+38 | R28: =IFERROR(Table3335466[[#This Row],[Max Count]]/Table3335466[[#This Row],[Scalar]],"") -> 3.4028235e+38 | W28: HREG_0044_Input_voltage_2_V
A29: 23 | B29: Available | C29: Holding Register | D29: POA | E29: 32-bit float | F29: 46 | H29: 40023 | M29: W/m2 | N29: 1 | O29: -3.4028235e+38 | P29: 3.4028235e+38 | Q29: =IFERROR(Table3335466[[#This Row],[Min Count]]/Table3335466[[#This Row],[Scalar]],"") -> -3.4028235e+38 | R29: =IFERROR(Table3335466[[#This Row],[Max Count]]/Table3335466[[#This Row],[Scalar]],"") -> 3.4028235e+38 | W29: HREG_0046_POA_W_per_m2
A30: 24 | B30: Available | C30: Holding Register | D30: POA temperature compensated | E30: 32-bit float | F30: 48 | H30: 40024 | M30: W/m2 | N30: 1 | O30: -3.4028235e+38 | P30: 3.4028235e+38 | Q30: =IFERROR(Table3335466[[#This Row],[Min Count]]/Table3335466[[#This Row],[Scalar]],"") -> -3.4028235e+38 | R30: =IFERROR(Table3335466[[#This Row],[Max Count]]/Table3335466[[#This Row],[Scalar]],"") -> 3.4028235e+38 | W30: HREG_0048_POA_temperature_compensated_W_per_m2
A31: 25 | B31: Available | C31: Holding Register | D31: POA temp | E31: 32-bit float | F31: 50 | H31: 40025 | M31: DegC | N31: 1 | O31: -3.4028235e+38 | P31: 3.4028235e+38 | Q31: =IFERROR(Table3335466[[#This Row],[Min Count]]/Table3335466[[#This Row],[Scalar]],"") -> -3.4028235e+38 | R31: =IFERROR(Table3335466[[#This Row],[Max Count]]/Table3335466[[#This Row],[Scalar]],"") -> 3.4028235e+38 | W31: HREG_0050_POA_temp_DegC
A32: 26 | B32: Available | C32: Holding Register | D32: GHI 1 | E32: 32-bit float | F32: 52 | H32: 40026 | M32: W/m2 | N32: 1 | O32: -3.4028235e+38 | P32: 3.4028235e+38 | Q32: =IFERROR(Table3335466[[#This Row],[Min Count]]/Table3335466[[#This Row],[Scalar]],"") -> -3.4028235e+38 | R32: =IFERROR(Table3335466[[#This Row],[Max Count]]/Table3335466[[#This Row],[Scalar]],"") -> 3.4028235e+38 | W32: HREG_0052_GHI_1_W_per_m2
... A119: 113 | B119: Available | C119: Holding Register | D119: Modeled POA | E119: 32-bit float | F119: 804 | H119: 40113 | M119: W/m2 | N119: 1 | O119: -3.4028235e+38 | P119: 3.4028235e+38 | Q119: =IFERROR(Table3335466[[#This Row],[Min Count]]/Table3335466[[#This Row],[Scalar]],"") -> -3.4028235e+38 | R119: =IFERROR(Table3335466[[#This Row],[Max Count]]/Table3335466[[#This Row],[Scalar]],"") -> 3.4028235e+38 | W119: HREG_0804_Modeled_POA_W_per_m2
A120: 114 | B120: Available | C120: Holding Register | D120: Summary alarm | E120: 32-bit unsigned int | F120: 2000 | H120: 40114 | J120: On (1) | K120: Alarm | L120: Normal | Q120: =IFERROR(Table3335466[[#This Row],[Min Count]]/Table3335466[[#This Row],[Scalar]],"") | R120: =IFERROR(Table3335466[[#This Row],[Max Count]]/Table3335466[[#This Row],[Scalar]],"") | W120: HREG_2000_Summary_alarm
A121: 115 | B121: Available | C121: Holding Register | D121: Data logger alarms register | E121: 32-bit unsigned int | F121: 2002 | H121: 40115 | M121: unitless | N121: 1 | Q121: =IFERROR(Table3335466[[#This Row],[Min Count]]/Table3335466[[#This Row],[Scalar]],"") | R121: =IFERROR(Table3335466[[#This Row],[Max Count]]/Table3335466[[#This Row],[Scalar]],"") | W121: HREG_2002_Data_logger_alarms_register
A122: 116 | B122: Available | C122: Holding Register | D122: Data logger watchdog error | E122: Boolean | F122: 2002 | G122: 0 | H122: 40116 | J122: On (1) | K122: Alarm | L122: Normal | Q122: =IFERROR(Table3335466[[#This Row],[Min Count]]/Table3335466[[#This Row],[Scalar]],"") | R122: =IFERROR(Table3335466[[#This Row],[Max Count]]/Table3335466[[#This Row],[Scalar]],"") | W122: HREG_2002_Data_logger_watchdog_error
A123: 117 | B123: Available | C123: Holding Register | D123: Data logger skipped main scan | E123: Boolean | F123: 2002 | G123: 1 | H123: 40117 | J123: On (1) | K123: Alarm | L123: Normal | Q123: =IFERROR(Table3335466[[#This Row],[Min Count]]/Table3335466[[#This Row],[Scalar]],"") | R123: =IFERROR(Table3335466[[#This Row],[Max Count]]/Table3335466[[#This Row],[Scalar]],"") | W123: HREG_2002_Data_logger_skipped_main_scan
A124: 118 | B124: Available | C124: Holding Register | D124: Data logger skipped slow scan | E124: Boolean | F124: 2002 | G124: 2 | H124: 40118 | J124: On (1) | K124: Alarm | L124: Normal | Q124: =IFERROR(Table3335466[[#This Row],[Min Count]]/Table3335466[[#This Row],[Scalar]],"") | R124: =IFERROR(Table3335466[[#This Row],[Max Count]]/Table3335466[[#This Row],[Scalar]],"") | W124: HREG_2002_Data_logger_skipped_slow_scan
A125: 119 | B125: Available | C125: Holding Register | D125: Data logger program variable out of bounds | E125: Boolean | F125: 2002 | G125: 3 | H125: 40119 | J125: On (1) | K125: Alarm | L125: Normal | Q125: =IFERROR(Table3335466[[#This Row],[Min Count]]/Table3335466[[#This Row],[Scalar]],"") | R125: =IFERROR(Table3335466[[#This Row],[Max Count]]/Table3335466[[#This Row],[Scalar]],"") | W125: HREG_2002_Data_logger_program_variable_out_of_bounds
A126: 120 | B126: Available | C126: Holding Register | D126: Data logger low 12V | E126: Boolean | F126: 2002 | G126: 4 | H126: 40120 | J126: On (1) | K126: Alarm | L126: Normal | Q126: =IFERROR(Table3335466[[#This Row],[Min Count]]/Table3335466[[#This Row],[Scalar]],"") | R126: =IFERROR(Table3335466[[#This Row],[Max Count]]/Table3335466[[#This Row],[Scalar]],"") | W126: HREG_2002_Data_logger_low_12V
...

Sheet Soiling to PPC - Eclipse 1.0
A1: ='Data Flows'!A1 -> Site Name | G1: Modbus | K1: Soiling to PPC
A2: Last updated | C2: 45643 | D2: Device Type | E2: Groundwork Eclipse | K2: The scalar is the multiplier to put the actual measurement value on the wire, and the divisor to take the actual measurement value off the wire.
A3: Index digits in name | C3: 4 | D3: Subsystem / Zone | E3: Environmental
A4: Device Register Base | C4: 1
A5: Register Digits | C5: 5
A6: List Index | B6: Availability | C6: Modbus Table | D6: Point Description | E6: Data Type | F6: RTAC Modbus index | G6: Modbus Bit | H6: Modbus Register | I6: Alarm State | J6: On (1) State | K6: Off (0) State | L6: Units | M6: Scalar | N6: Min Count | O6: Max Count | P6: Min Value | Q6: Max Value | R6: Analog Alarm Limits | S6: Alarm Profile | T6: Historian Profile | U6: HMI Category | V6: RTAC Point Name | W6: Enumeration Table | X6: Comments
A7: 1 | B7: Available | C7: Holding Register | D7: Scan count | E7: 32-bit float | F7: 0 | H7: 40001 | L7: s | M7: 1 | N7: 1 | V7: HREG_0000_Scan_count_s
A8: 2 | B8: Available | C8: Holding Register | D8: Skipped scans | E8: 32-bit float | F8: 2 | H8: 40003 | L8: count | M8: 1 | N8: 1 | V8: HREG_0002_Skipped_scans_count
A9: 3 | B9: Available | C9: Holding Register | D9: Logger voltage | E9: 32-bit float | F9: 4 | H9: 40005 | L9: V | M9: 1 | N9: 1 | V9: HREG_0004_Logger_voltage_V
A10: 4 | B10: Available | C10: Holding Register | D10: Logger temp | E10: 32-bit float | F10: 6 | H10: 40007 | L10: DegC | M10: 1 | N10: 1 | V10: HREG_0006_Logger_temp_DegC
A11: 5 | B11: Available | C11: Holding Register | D11: Skipped slow scans | E11: 32-bit float | F11: 8 | H11: 40009 | L11: count | M11: 1 | N11: 1 | V11: HREG_0008_Skipped_slow_scans_count
A12: 6 | B12: Available | C12: Holding Register | D12: Logger lithium | E12: 32-bit float | F12: 10 | H12: 40011 | L12: V | M12: 1 | N12: 1 | V12: HREG_0010_Logger_lithium_V
A13: 7 | B13: Available | C13: Holding Register | D13: Logger low volt 12 | E13: 32-bit float | F13: 12 | H13: 40013 | L13: count | M13: 1 | N13: 1 | V13: HREG_0012_Logger_low_volt_12_count
A14: 8 | B14: Available | C14: Holding Register | D14: Solar zenith | E14: 32-bit float | F14: 16 | H14: 40017 | L14: degrees | M14: 1 | N14: 1 | V14: HREG_0016_Solar_zenith_degrees
A15: 9 | B15: Available | C15: Holding Register | D15: Solar elevation | E15: 32-bit float | F15: 18 | H15: 40019 | L15: degrees | M15: 1 | N15: 1 | V15: HREG_0018_Solar_elevation_degrees
A16: 10 | B16: Available | C16: Holding Register | D16: Solar azimuth | E16: 32-bit float | F16: 20 | H16: 40021 | L16: degrees | M16: 1 | N16: 1 | V16: HREG_0020_Solar_azimuth_degrees
A17: 11 | B17: Available | C17: Holding Register | D17: Logger data map version | E17: 32-bit float | F17: 24 | H17: 40025 | L17: unitless | M17: 1 | N17: 1 | V17: HREG_0024_Logger_data_map_version
A18: 12 | B18: Available | C18: Holding Register | D18: Maint event | E18: 32-bit float | F18: 26 | H18: 40027 | L18: enumeration | M18: 1 | N18: 1 | V18: HREG_0026_Maint_event_enumaration | W18: Soiling Status: 0 - Normal 1 - Maintenance in last 24 hours 2 - Normalization in last 5 minutes
A19: 13 | B19: Available | C19: Holding Register | D19: ISC clean | E19: 32-bit float | F19: 138 | H19: 40139 | L19: A | M19: 1 | N19: 1 | V19: HREG_0138_ISC_clean_A
A20: 14 | B20: Available | C20: Holding Register | D20: ISC soiled | E20: 32-bit float | F20: 140 | H20: 40141 | L20: A | M20: 1 | N20: 1 | V20: HREG_0140_ISC_soiled_A
A21: 15 | B21: Available | C21: Holding Register | D21: Daily soiling loss factor | E21: 32-bit float | F21: 142 | H21: 40143 | L21: PU | M21: 1 | N21: 1 | V21: HREG_0142_Daily_soiling_loss_factor
A22: 16 | B22: Available | C22: Holding Register | D22: Daily soiling ISC ratio | E22: 32-bit float | F22: 144 | H22: 40145 | L22: PU | M22: 1 | N22: 1 | V22: HREG_0144_Daily_soiling_ISC_ratio
A23: 17 | B23: Available | C23: Holding Register | D23: BOM temp clean | E23: 32-bit float | F23: 146 | H23: 40147 | L23: DegC | M23: 1 | N23: 1 | V23: HREG_0146_BOM_temp_clean_DegC
A24: 18 | B24: Available | C24: Holding Register | D24: BOM temp soiled | E24: 32-bit float | F24: 148 | H24: 40149 | L24: DegC | M24: 1 | N24: 1 | V24: HREG_0148_BOM_temp_soiled_DegC
A25: 19 | B25: Available | C25: Holding Register | D25: Soiling loss factor | E25: 32-bit float | F25: 150 | H25: 40151 | L25: PU | M25: 1 | N25: 1 | V25: HREG_0150_Soiling_loss_factor
A26: 20 | B26: Available | C26: Holding Register | D26: Soiling ISC ratio | E26: 32-bit float | F26: 152 | H26: 40153 | L26: PU | M26: 1 | N26: 1 | V26: HREG_0152_Soiling_ISC_ratio
A27: 21 | B27: Available | C27: Holding Register | D27: ISC normalized soiled | E27: 32-bit float | F27: 154 | H27: 40155 | L27: A | M27: 1 | N27: 1 | V27: HREG_0154_ISC_normalized_soiled_A
A28: 22 | B28: Available | C28: Holding Register | D28: G clean | E28: 32-bit float | F28: 156 | H28: 40157 | L28: W/m2 | M28: 1 | N28: 1 | V28: HREG_0156_G_clean_W_per_m2
A29: 23 | B29: Available | C29: Holding Register | D29: G soiled | E29: 32-bit float | F29: 158 | H29: 40159 | L29: W/m2 | M29: 1 | N29: 1 | V29: HREG_0158_G_soiled_W_per_m2
A30: 24 | B30: Available | C30: Holding Register | D30: Soiling status | E30: 32-bit float | F30: 160 | H30: 40161 | L30: enumeration | M30: 1 | N30: 1 | V30: HREG_0160_Soiling_status_enumeration | W30: Soiling Status: 0 - Normal 1 - Maintenance in last 24 hours 2 - Normalization in last 5 minutes
A31: 25 | B31: Available | C31: Holding Register | D31: Voc clean | E31: 32-bit float | F31: 162 | H31: 40163 | L31: V | M31: 1 | N31: 1 | U31: Voc clean | V31: HREG_0162_Voc_clean_V
A32: 26 | B32: Available | C32: Holding Register | D32: Voc soiled | E32: 32-bit float | F32: 164 | H32: 40165 | L32: V | M32: 1 | N32: 1 | U32: Voc soiled | V32: HREG_0164_Voc_soiled_V
A33: 27 | B33: Available | C33: Holding Register | D33: Hourly ISC clean avg | E33: 32-bit float | F33: 288 | H33: 40289 | L33: A | M33: 1 | N33: 1 | V33: HREG_0288_Hourly_ISC_clean_avg_A
A34: 28 | B34: Available | C34: Holding Register | D34: Hourly ISC soiled avg | E34: 32-bit float | F34: 290 | H34: 40291 | L34: A | M34: 1 | N34: 1 | V34: HREG_0290_Hourly_ISC_soiled_avg_A
A35: 29 | B35: Available | C35: Holding Register | D35: Hourly ISC normalized soiled | E35: 32-bit float | F35: 292 | H35: 40293 | L35: A | M35: 1 | N35: 1 | V35: HREG_0292_Hourly_ISC_normalized_soiled_A
A36: 30 | B36: Available | C36: Holding Register | D36: Hourly BOM temp clean avg | E36: 32-bit float | F36: 296 | H36: 40297 | L36: DegC | M36: 1 | N36: 1 | V36: HREG_0296_Hourly_BOM_temp_clean_avg_DegC
A37: 31 | B37: Available | C37: Holding Register | D37: Hourly BOM temp soiled avg | E37: 32-bit float | F37: 298 | H37: 40299 | L37: DegC | M37: 1 | N37: 1 | V37: HREG_0298_Hourly_BOM_temp_soiled_avg_DegC
A38: 32 | B38: Available | C38: Holding Register | D38: Hourly soiling loss factor avg | E38: 32-bit float | F38: 300 | H38: 40301 | L38: PU | M38: 1 | N38: 1 | V38: HREG_0300_Hourly_soiling_loss_factor_avg
A39: 33 | B39: Available | C39: Holding Register | D39: Hourly soiling ISC ratio avg | E39: 32-bit float | F39: 302 | H39: 40303 | L39: PU | M39: 1 | N39: 1 | V39: HREG_0302_Hourly_soiling_ISC_ratio_avg
A40: 34 | B40: Available | C40: Holding Register | D40: Hourly G clean avg | E40: 32-bit float | F40: 304 | H40: 40305 | L40: W/m2 | M40: 1 | N40: 1 | V40: HREG_0304_Hourly_G_clean_avg_W_per_m2
...

Sheet Soiling to PPC - DustIQ
A1: Hornshadow | G1: Modbus | K1: Soiling to PPC
A2: Last updated | C2: 45643 | D2: Device Type | E2: Groundwork Eclipse | K2: The scalar is the multiplier to put the actual measurement value on the wire, and the divisor to take the actual measurement value off the wire.
A3: Index digits in name | C3: 4 | D3: Subsystem / Zone | E3: Environmental
A4: Device Register Base | C4: 1
A5: Register Digits | C5: 5
A6: List Index | B6: Availability | C6: Modbus Table | D6: Point Description | E6: Data Type | F6: RTAC Modbus index | G6: Modbus Bit | H6: Modbus Register | I6: Alarm State | J6: On (1) State | K6: Off (0) State | L6: Units | M6: Scalar | N6: Min Count | O6: Max Count | P6: Min Value | Q6: Max Value | R6: Analog Alarm Limits | S6: Alarm Profile | T6: Historian Profile | U6: HMI Category | V6: RTAC Point Name | W6: Enumeration Table | X6: Comments
A7: 1 | B7: Available | C7: Input Register | D7: Soiling Ratio Sensor 1 | E7: 16-bit Unsigned Integer | F7: 20 | H7: 30021 | L7: % | M7: 0.1 | N7: 1 | V7: IREG_020_soiling_raio_1 | X7: In steps of 0.1%, 9999 when not valid
A8: 2 | B8: Available | C8: Input Register | D8: Transmission Loss Sensor 1 | E8: 16-bit Signed Integer | F8: 21 | H8: 30022 | L8: % | M8: 0.1 | N8: 1 | V8: IREG_021_transmission_loss_1 | X8: In steps of 0.1%, 9999 when not valid
A9: 3 | B9: Available | C9: Input Register | D9: Soiling Ratio Sensor 2 | E9: 16-bit Unsigned Integer | F9: 24 | H9: 30025 | L9: % | M9: 0.1 | N9: 1 | V9: IREG_024_soiling_ratio_2 | X9: In steps of 0.1%, 9999 when not valid
A10: 4 | B10: Available | C10: Input Register | D10: Transmission Loss Sensor 2 | E10: 16-bit Signed Integer | F10: 25 | H10: 30026 | L10: % | M10: 0.1 | N10: 1 | V10: IREG_025_transmission_loss_2 | X10: In steps of 0.1%, 9999 when not valid
A11: 5 | B11: Available | C11: Input Register | D11: Tilt X Direction ( Long Axis) | E11: 16-bit Signed Integer | F11: 28 | H11: 30029 | L11: Degrees | M11: 0.1 | N11: 1 | V11: IREG_028_tilt_x_deg | X11: In steps of 0.1 degrees
A12: 6 | B12: Available | C12: Input Register | D12: Tilt Y Direction (Short Axis) | E12: 16-bit Signed Integer | F12: 29 | H12: 30030 | L12: Degrees | M12: 0.1 | N12: 1 | V12: IREG_029_tilt_y_deg | X12: In steps of 0.1 degrees
A13: 7 | B13: Available | C13: Input Register | D13: Back Panel Temperature | E13: 16-bit Unsigned Integer | F13: 31 | H13: 30032 | L13: Deg K | M13: 0.1 | N13: 1 | V13: IREG_031_back_panel_temperature_K | X13: In steps 0.1 Kelvin
A14: 8 | B14: Available | C14: Input Register | D14: Device Voltage | E14: 16-bit Unsigned Integer | F14: 32 | H14: 30033 | L14: mV | M14: 1 | N14: 1 | V14: IREG_032_device_voltage_mV | X14: Device voltage at the input connector
A15: 9 | B15: Available | C15: Input Register | D15: Operational Mode | E15: 16-bit Unsigned Integer | F15: 33 | H15: 30034 | L15: degrees | M15: 1 | N15: 1 | V15: IREG_033_operational_mode | W15: Normal = 1, Service = 2, Calibration = 3
A16: 10 | B16: Available | C16: Input Register | D16: Device Status Flags | E16: 16-bit Unsigned Integer | F16: 34 | H16: 30035 | L16: degrees | M16: 1 | N16: 1 | V16: IREG_034_device_status | W16: 0 = Status OK

Sheet Albedometers to PPC
A1: ='Data Flows'!A1 -> Site Name | G1: Modbus | K1: Albedometers to PPC
A2: Last updated | C2: 45643 | D2: Device Type | E2: Groundwork Eclipse | K2: The scalar is the multiplier to put the actual measurement value on the wire, and the divisor to take the actual measurement value off the wire.
A3: Index digits in name | C3: 4 | D3: Subsystem / Zone | E3: Environmental
A4: Device Register Base | C4: 1
A5: Register Digits | C5: 5
A6: List Index | B6: Availability | C6: Modbus Table | D6: Point Description | E6: Data Type | F6: RTAC Modbus index | G6: Modbus Bit | H6: Modbus Register | I6: Alarm State | J6: On (1) State | K6: Off (0) State | L6: Units | M6: Scalar | N6: Min Count | O6: Max Count | P6: Min Value | Q6: Max Value | R6: Analog Alarm Limits | S6: Alarm Profile | T6: Historian Profile | U6: HMI Category | V6: RTAC Point Name | W6: Enumeration Table | X6: Comments
A7: 1 | B7: Available | C7: Holding Register | D7: Scan count | E7: 32-bit float | F7: 0 | H7: 40001 | L7: Sec | M7: 1 | N7: 1 | O7: -3.4028235e+38 | P7: 3.4028235e+38 | Q7: -3.4028235e+38 | V7: HREG_0000_Scan_count_Sec
